Workbook

Sheet INGRESO WENDY
A1: WENDY
A2: ITEM | C2: SEMANA | D2: FECHA | E2: BOLIVARES | F2: TASA | G2: DOLARES CONV. | H2: EFECTIVO | I2: EFECTIVO BS CONVERTIDOS | J2: DOLARES EFECTIVO | K2: ZELLE | L2: C X C | M2: VENTA DIARIA | O2: VENTA REAL TIENDA | Q2: PAGOS DE VENDEDORES | S2: PAGOS DE VENDEDORES $
A3: 1 | C3: JUEVES | D3: 46149 | E3: =16965+13702.5+36836.39 -> 67503.89 | F3: 652.5 | G3: =+E3/F3 -> 103.45424 | J3: 0 | K3: 0 | L3: =174+103+522 -> 799 | M3: =+G3+J3+K3+L3+I3 -> 902.45424 | O3: =+M3-L3 -> 103.45424 | Q3: 69895.8 | S3: 174
A4: 2 | C4: VIERNES | D4: 46150 | E4: =57306.9+17126.2+72391.6 -> 146824.7 | F4: 658.7 | G4: =+E4/F4 -> 222.90071 | J4: 9 | K4: 0 | L4: 26 | M4: =+G4+J4+K4+L4+I4 -> 257.90071 | O4: =+M4-L4 -> 231.90071 | Q4: 109340.72
A5: 3 | C5: LUNES | D5: 46153 | E5: =4533.2+40151.2+4533.2 -> 49217.6 | F5: 647.6 | G5: =+E5/F5 -> 76 | J5: 0 | K5: 0 | L5: 184 | M5: =+G5+J5+K5+L5+I5 -> 260 | O5: =+M5-L5 -> 76 | V5: MIERCOLES
A6: 4 | C6: MARTES | D6: 46154 | E6: =4562.88+43673.28 -> 48236.16 | F6: 651.84 | G6: =+E6/F6 -> 74 | J6: 0 | K6: 106 | L6: 0 | M6: =+G6+J6+K6+L6+I6 -> 180 | O6: =+M6-L6 -> 180 | U6: FECHA | V6: 46169
A7: 5 | C7: MIERCOLES | D7: 46155 | E7: 46218.9 | F7: 660.27 | G7: =+E7/F7 -> 70 | J7: 0 | K7: 0 | L7: =348+481.5 -> 829.5 | M7: =+G7+J7+K7+L7+I7 -> 899.5 | O7: =+M7-L7 -> 70 | U7: TASA | V7: 734.9
A8: 6 | C8: JUEVES | D8: 46156 | E8: 34606.52 | F8: 665.51 | G8: =+E8/F8 -> 52 | J8: 0 | K8: 0 | L8: 0 | M8: =+G8+J8+K8+L8+I8 -> 52 | O8: =+M8-L8 -> 52 | U8: $ | V8: 0 | W8: 20
A9: 7 | C9: VIERNS | D9: 46157 | E9: =37011.7+4710.57+20861.12 -> 62583.39 | F9: 672.94 | G9: =+E9/F9 -> 92.999955 | J9: 112 | K9: 0 | M9: =+G9+J9+K9+L9+I9 -> 204.99996 | O9: =+M9-L9 -> 204.99996 | S9: 160 | U9: EFECTIVO BS | V9: 7000 | W9: =+V9/V7 -> 9.5251055
A10: 8 | C10: LUNES | D10: 46160 | E10: =71424.19+23808.16 -> 95232.35 | F10: 700.24 | G10: =+E10/F10 -> 135.99959 | J10: 0 | K10: 165 | L10: =14+92+127 -> 233 | M10: =+G10+J10+K10+L10+I10 -> 533.99959 | O10: =+M10-L10 -> 300.99959 | Q10: 5601.92 | S10: 600 | U10: BANCO | V10: =+E17 -> 51057.1 | W10: =+V10/V7 -> 69.474895
A11: 9 | C11: MARTES | D11: 46161 | E11: 0 | F11: 714.74 | G11: =+E11/F11 -> 0 | J11: 20 | K11: 0 | L11: 0 | M11: =+G11+J11+K11+L11+I11 -> 20 | O11: =+M11-L11 -> 20 | U11: ZELLE | V11: 0 | W11: 0
A12: 10 | C12: MIERCOLES | D12: 46162 | E12: =23218.47+48547.71 -> 71766.18 | F12: 703.59 | G12: =+E12/F12 -> 102 | J12: 62 | K12: 0 | L12: 516 | M12: =+G12+J12+K12+L12+I12 -> 680 | O12: =+M12-L12 -> 164 | U12: BINANCE | W12: 0
A13: 11 | C13: JUEVES | D13: 46163 | E13: =13542.06+14254.8 -> 27796.86 | F13: 712.74 | G13: =+E13/F13 -> 39 | J13: 123 | K13: 0 | M13: =+G13+J13+K13+L13+I13 -> 162 | O13: =+M13-L13 -> 162 | U13: TOTAL TIENDA | W13: =+W8+W9+W10+W11+W12 -> 99
A14: 12 | C14: VIERNES | D14: 46164 | E14: =24926+27189+5008.5 -> 57123.5 | F14: 715.5 | G14: =+E14/F14 -> 79.837177 | J14: 174 | K14: 0 | L14: =81+260 -> 341 | M14: =+G14+J14+K14+L14+I14 -> 594.83718 | O14: =+M14-L14 -> 253.83718 | U14: CXC | W14: 870
A15: 13 | C15: LUNES | D15: 46167 | E15: =134788.63+8696.04+5072.69 -> 148557.36 | F15: 724.67 | G15: =+E15/F15 -> 205.00001 | J15: 64 | L15: =38+610+92 -> 740 | M15: =+G15+J15+K15+L15+I15 -> 1009 | O15: =+M15-L15 -> 269.00001 | Q15: =24783.42+33486 -> 58269.42 | S15: 148.5 | U15: TOTAL DEL DIA | W15: =+W13+W14 -> 969
A16: 14 | C16: MARTES | D16: 46168 | E16: =54408.4+18613.39+10022.6 -> 83044.39 | F16: 715.9 | G16: =+E16/F16 -> 115.99999 | J16: 7 | K16: 0 | L16: 605 | M16: =+G16+J16+K16+L16+I16 -> 727.99999 | O16: =+M16-L16 -> 122.99999 | S16: 85.5
A17: 15 | C17: MIERCOLES | D17: 46169 | E17: =21312.1+7698+22047 -> 51057.1 | F17: 734.9 | G17: =+E17/F17 -> 69.474895 | H17: 7000 | I17: =+H17/F17 -> 9.5251055 | J17: 20 | K17: 0 | L17: 870 | M17: =+G17+J17+K17+L17+I17 -> 969 | O17: =+M17-L17 -> 99
A18: 16 | M18: =+G18+J18+K18+L18+I18 -> 0
A19: 17 | M19: =+G19+J19+K19+L19+I19 -> 0
A20: 18 | M20: =+G20+J20+K20+L20 -> 0
A21: 19 | M21: =+G21+J21+K21+L21 -> 0
A22: 20 | M22: =+G22+J22+K22+L22 -> 0
A23: 21 | M23: =+G23+J23+K23+L23 -> 0
A24: 22 | M24: =+G24+J24+K24+L24 -> 0
A25: 23 | M25: =+G25+J25+K25+L25 -> 0
A26: 24 | M26: =+G26+J26+K26+L26 -> 0
A27: 25 | M27: =+G27+J27+K27+L27 -> 0
A28: 26 | M28: =+G28+J28+K28+L28 -> 0
A29: 27 | M29: =+G29+J29+K29+L29 -> 0
A30: 28 | M30: =+G30+J30+K30+L30 -> 0
A31: 29 | M31: =+G31+J31+K31+L31 -> 0
... A63: 61 | M63: =+G63+J63+K63+L63 -> 0
D64: TOTAL: | E64: =SUM(E3:E63) -> 989768.9 | H64: 7000 | I64: =SUM(I3:I63) -> 9.5251055 | J64: =SUM(J3:J63) -> 591 | K64: =SUM(K3:K63) -> 271 | L64: =SUM(L3:L63) -> 5143.5 | M64: =SUM(M3:M63) -> 7453.6917 | O64: =SUM(O3:O63) -> 2310.1917 | Q64: =SUM(Q3:Q18) -> 243107.86 | S64: =SUM(S3:S18) -> 1168

Sheet CREDITO
A1: ITEM | B1: N° NOTA | C1: FECHA | D1: DONACION | E1: GARANTIA | F1: JESUS RUIZ 1 | G1: ISAAC RANGEL 2 | H1: LUIS QUERALES 3 | I1: BETSI | J1: ELIZABETH G | K1: JAIRO | L1: DANYELLO C | M1: TOTY | N1: VENDEDOR 9 | O1: VENDEDOR 10 | P1: VENDEDOR 11 | Q1: TOTAL
A2: 1 | B2: 376 | C2: 46149 | F2: 522 | Q2: =SUM(D2:P2) -> 522 | R2: =+Q2+Q3+Q4 -> 803.12
A3: 2 | B3: 377 | C3: 46149 | F3: 174 | Q3: =SUM(D3:P3) -> 174
A4: 3 | B4: 378 | C4: 46149 | I4: 107.12 | Q4: =SUM(D4:P4) -> 107.12
A5: 4 | B5: 387 | C5: 46150 | L5: 26 | Q5: =SUM(D5:P5) -> 26 | R5: =+Q5 -> 26
A6: 5 | B6: 391 | C6: 46153 | L6: 184 | Q6: =SUM(D6:P6) -> 184 | R6: =+Q6 -> 184
A7: 6 | B7: 397 | C7: 46155 | F7: 348 | Q7: =SUM(D7:P7) -> 348 | R7: 829.5
A8: 7 | B8: 402 | C8: 46155 | D8: 481.5 | Q8: =SUM(D8:P8) -> 481.5
A9: 8 | B9: 412 | C9: 46160 | F9: 127 | Q9: =SUM(D9:P9) -> 127 | R9: =+Q9+Q10+Q11 -> 233
A10: 9 | B10: 413 | C10: 46160 | F10: 92 | Q10: =SUM(D10:P10) -> 92
A11: 10 | B11: 412 | C11: 46160 | L11: 14 | Q11: =SUM(D11:P11) -> 14
A12: 11 | B12: 430 | C12: 46162 | F12: 174 | Q12: =SUM(D12:P12) -> 174 | R12: =+Q12+Q13 -> 516
A13: 12 | B13: 432 | C13: 46162 | F13: 342 | Q13: =SUM(D13:P13) -> 342
A14: 13 | B14: 440 | C14: 46164 | L14: 81 | Q14: =SUM(D14:P14) -> 81 | R14: =+Q14+Q15 -> 341
A15: 14 | B15: 443 | C15: 46164 | M15: 260 | Q15: =SUM(D15:P15) -> 260
A16: 15 | B16: 444 | C16: 46167 | F16: 92 | Q16: =SUM(D16:P16) -> 92 | R16: =+Q16+Q17+Q18 -> 740
A17: 16 | B17: 445 | C17: 46167 | F17: 610 | Q17: =SUM(D17:P17) -> 610
A18: 17 | B18: 454 | C18: 46167 | L18: 38 | Q18: =SUM(D18:P18) -> 38
A19: 18 | B19: 455 | C19: 46168 | G19: 605 | Q19: =SUM(D19:P19) -> 605 | R19: 605
A20: 19 | C20: 46169 | J20: 870 | Q20: =SUM(D20:P20) -> 870
A21: 20 | Q21: =SUM(D21:P21) -> 0
A22: 21 | Q22: =SUM(D22:P22) -> 0
A23: 22 | Q23: =SUM(D23:P23) -> 0
A24: 23 | Q24: =SUM(D24:P24) -> 0
A25: 24 | Q25: =SUM(D25:P25) -> 0
A26: 25 | Q26: =SUM(D26:P26) -> 0
A27: 26 | Q27: =SUM(D27:P27) -> 0
A28: 27 | Q28: =SUM(D28:P28) -> 0
A29: 28 | Q29: =SUM(D29:P29) -> 0
A30: 29 | Q30: =SUM(D30:P30) -> 0
A31: 30 | Q31: =SUM(D31:P31) -> 0
C32: CREDITO: | D32: =SUM(D2:D31) -> 481.5 | E32: =SUM(E2:E31) -> 0 | F32: =SUM(F2:F31) -> 2481 | G32: =SUM(G2:G31) -> 605 | H32: =SUM(H2:H31) -> 0 | I32: =SUM(I2:I31) -> 107.12 | J32: =SUM(J2:J31) -> 870 | K32: =SUM(K2:K31) -> 0 | ... Q32: =SUM(Q2:Q31) -> 5147.62 | R32: TOTAL CREDITO
C33: ABONOS: | D33: ='INGRESO DETALLADO INDIVIDUAL'!F65 -> 0 | E33: ='INGRESO DETALLADO INDIVIDUAL'!M65 -> 0 | F33: ='INGRESO DETALLADO INDIVIDUAL'!T65 -> 934 | G33: ='INGRESO DETALLADO INDIVIDUAL'!AA65 -> 8 | H33: ='INGRESO DETALLADO INDIVIDUAL'!AH65 -> 0 | I33: ='INGRESO DETALLADO INDIVIDUAL'!AO65 -> 107.12 | J33: ='INGRESO DETALLADO INDIVIDUAL'!AV65 -> 0 | K33: ='INGRESO DETALLADO INDIVIDUAL'!BC65 -> 0 | L33: ='INGRESO DETALLADO INDIVIDUAL'!BJ65 -> 265.00086 | M33: ='INGRESO DETALLADO INDIVIDUAL'!BQ65 -> 233 | N33: ='INGRESO DETALLADO INDIVIDUAL'!BX65 -> 0 | O33: ='INGRESO DETALLADO INDIVIDUAL'!CE65 -> 0 | P33: ='INGRESO DETALLADO INDIVIDUAL'!CL65 -> 0 | Q33: =SUM(D33:P33) -> 1547.1209 | R33: TOTAL ABONO
C34: C X C : | D34: =D32-D33 -> 481.5 | E34: =E32-E33 -> 0 | F34: =F32-F33 -> 1547 | G34: =G32-G33 -> 597 | H34: =H32-H33 -> 0 | I34: =I32-I33 -> 0 | J34: =J32-J33 -> 870 | K34: =K32-K33 -> 0 | ... P34: =P32-P33 -> 0 | Q34: =SUM(D34:P34) -> 3600.4991 | R34: TOTAL PENDIENTE
C35: COMISION | D35: 0 | E35: =+E32*10% -> 0 | F35: 0 | G35: =+G32*10% -> 60.5 | H35: =+H32*10% -> 0 | I35: 0 | J35: =+J32*10% -> 87 | K35: =+K32*10% -> 0 | L35: =+L32*10% -> 34.3 | M35: =+M32*10% -> 26 | N35: =+N32*10% -> 0 | O35: =+O32*10% -> 0 | P35: =+P32*10% -> 0 | Q35: =+D35+E35+F35+G35+H35+I35+J35+K35+L35+M35+N35+O35+P35 -> 207.8
C36: TOTAL VEND | D36: =+D32-D35 -> 481.5 | E36: =+E32-E35 -> 0 | F36: 0 | G36: =+G32-G35 -> 544.5 | H36: =+H32-H35 -> 0 | I36: =+I32-I35 -> 107.12 | J36: =+J32-J35 -> 783 | K36: =+K32-K35 -> 0 | L36: =+L32-L35 -> 308.7 | M36: =+M32-M35 -> 234 | N36: =+N32-N35 -> 0 | ... P36: =+P32-P35 -> 0 | Q36: =+D36+E36+F36+G36+H36+I36+J36+K36+L36+M36+N36+O36+P36 -> 2458.82
Q39: CXC | R39: =+Q32 -> 5147.62
Q40: ABONOS | R40: =+Q33 -> 1547.1209
Q41: ABONOS $ | R41: =+'INGRESOS DIARIOS INDIVIDUALES'!H64+'INGRESOS DIARIOS INDIVIDUALES'!I64 -> 1168
Q42: ABONOS BS | R42: =+'INGRESOS DIARIOS INDIVIDUALES'!G64 -> 361.72086 | S42: =+R41+R42 -> 1529.7209
...

Sheet INGRESOS DIARIOS INDIVIDUALES
A1: WENDY
A2: ITEM | B2: VENDEDOR | C2: DIA | D2: FECHA | E2: BOLIVARES | F2: TASA | G2: DOLARES CONV. | H2: DOLARES EFECTIVO | I2: ZELLE
A3: 1 | B3: JESUS RUIZ | C3: JUEVES | D3: 46149 | H3: 174 | I3: 0
A4: 2 | B4: BETSY | C4: JUEVES | D4: 46149 | E4: 69895.8 | F4: 652.5 | G4: =+E4/F4 -> 107.12 | H4: 0 | I4: 0
A5: 3
A6: 4 | B6: DANYELLO | C6: MIERCOLES | D6: 46155 | E6: 109340.72 | F6: 660.27 | G6: =+E6/F6 -> 165.60001
A7: 5 | B7: JESUS RUIZ | C7: VIERNES | D7: 46157 | E7: 0 | F7: 0 | G7: 0 | H7: 0 | I7: 160
A8: 6 | B8: ISACC RANGEL | C8: LUNES | D8: 46160 | E8: 5601.92 | F8: 700.24 | G8: =+E8/F8 -> 8 | H8: 0 | I8: 0
A9: 7 | B9: DANYELLO | C9: SABADO | D9: 46165 | E9: 33486 | F9: 715.5 | G9: =+E9/F9 -> 46.800839
A10: 8 | B10: JESUS RUIZ | C10: LUNES | D10: 46165 | I10: 600
A11: 9 | B11: TOTI | C11: LUNES | D11: 46167 | I11: 148.5
A12: 10 | B12: DANYELLO | C12: LUNES | D12: 46167 | E12: 24783.72 | F12: 724.67 | G12: =+E12/F12 -> 34.200008
A13: 11 | B13: TOTI/JESUS | C13: LUNES | D13: 46167 | I13: 85.5
A14: 12
A15: 13
A16: 14
A17: 15
A18: 16
A19: 17
A20: 18
A21: 19
A22: 20
A23: 21
A24: 22
A25: 23
... A63: 61
D64: TOTAL: | E64: =SUM(E3:E63) -> 243108.16 | G64: =SUM(G4:G63) -> 361.72086 | H64: =SUM(H3:H63) -> 174 | I64: =SUM(I3:I63) -> 994 | J64: =SUM(G64:I64) -> 1529.7209 | K64: TOTAL INGRESO
G66: =+G64 -> 361.72086 | I66: =+H64+I64 -> 1168 | J66: =+G66+I66 -> 1529.7209

Sheet INGRESO DETALLADO INDIVIDUAL
A1: DONACION | H1: GARANTIA | O1: JESUS RUIZ 1 | V1: ISAAC RANGEL 2 | AC1: LUIS QUERALES 3 | AJ1: BETSI | AQ1: ELIZABETH | AX1: JAIRO | BE1: DANYELLO CALATAYUD | BL1: TOTI | BS1: VENDEDOR 9 | BZ1: VENDEDOR 10 | CG1: VENDEDOR 11
A2: ITEM | B2: FECHA | C2: BOLIVARES | D2: TASA | E2: DOLARES CONV. | F2: DOLARES | H2: ITEM | I2: FECHA | J2: BOLIVARES | K2: TASA | L2: DOLARES CONV. | M2: DOLARES | O2: ITEM | P2: FECHA | Q2: BOLIVARES | R2: TASA | S2: DOLARES CONV. | T2: DOLARES | V2: ITEM | W2: FECHA | X2: BOLIVARES | Y2: TASA | Z2: DOLARES CONV. | AA2: DOLARES | AC2: ITEM | AD2: FECHA | AE2: BOLIVARES | AF2: TASA | AG2: DOLARES CONV. | AH2: DOLARES | AJ2: ITEM | AK2: FECHA | AL2: BOLIVARES | AM2: TASA | AN2: DOLARES CONV. | AO2: DOLARES | AQ2: ITEM | AR2: FECHA | AS2: BOLIVARES | AT2: TASA | AU2: DOLARES CONV. | AV2: DOLARES | AX2: ITEM | AY2: FECHA | AZ2: BOLIVARES | BA2: TASA | BB2: DOLARES CONV. | BC2: DOLARES | BE2: ITEM | BF2: FECHA | BG2: BOLIVARES | BH2: TASA | BI2: DOLARES CONV. | BJ2: DOLARES | BL2: ITEM | BM2: FECHA | BN2: BOLIVARES | BO2: TASA | BP2: DOLARES CONV. | BQ2: DOLARES | BS2: ITEM | BT2: FECHA | BU2: BOLIVARES | BV2: TASA | BW2: DOLARES CONV. | BX2: DOLARES | BZ2: ITEM | CA2: FECHA | CB2: BOLIVARES | CC2: TASA | CD2: DOLARES CONV. | CE2: DOLARES | CG2: ITEM | CH2: FECHA | CI2: BOLIVARES | CJ2: TASA | CK2: DOLARES CONV. | CL2: DOLARES
A3: 1 | F3: 0 | H3: 1 | O3: 1 | P3: 46149 | T3: 174 | V3: 1 | W3: 46160 | X3: 5601.92 | Y3: 700.24 | Z3: =+X3/Y3 -> 8 | AC3: 1 | AJ3: 1 | AK3: 46149 | AL3: 69895.8 | AM3: 652.5 | AN3: =+AL3/AM3 -> 107.12 | AQ3: 1 | AX3: 1 | BE3: 1 | BF3: 46155 | BG3: 109340.72 | BH3: 660.27 | BI3: =+BG3/BH3 -> 165.60001 | BL3: 1 | BM3: 46167 | BQ3: 148.5 | BS3: 1 | BZ3: 1 | CG3: 1
A4: 2 | H4: 2 | O4: 2 | P4: 46157 | T4: 160 | V4: 2 | AC4: 2 | AJ4: 2 | AQ4: 2 | AX4: 2 | BE4: 2 | BF4: 46155 | BG4: =+BH4*BI4 -> 12148.968 | BH4: 660.27 | BI4: 18.4 | BL4: 2 | BM4: 46167 | BQ4: 84.5 | BS4: 2 | BZ4: 2 | CG4: 2
A5: 3 | H5: 3 | O5: 3 | P5: 46165 | T5: 600 | V5: 3 | AC5: 3 | AH5: 0 | AJ5: 3 | AQ5: 3 | AX5: 3 | BE5: 3 | BF5: 46165 | BG5: 33486 | BH5: 715.5 | BI5: =+BG5/BH5 -> 46.800839 | BL5: 3 | BS5: 3 | BZ5: 3 | CG5: 3
A6: 4 | H6: 4 | O6: 4 | V6: 4 | AC6: 4 | AJ6: 4 | AQ6: 4 | AX6: 4 | BE6: 4 | BF6: 46167 | BG6: 24783.72 | BH6: 724.67 | BI6: =+BG6/BH6 -> 34.200008 | BL6: 4 | BS6: 4 | BZ6: 4 | CG6: 4
A7: 5 | H7: 5 | O7: 5 | V7: 5 | AC7: 5 | AJ7: 5 | AQ7: 5 | AX7: 5 | BE7: 5 | BL7: 5 | BS7: 5 | BZ7: 5 | CG7: 5
A8: 6 | H8: 6 | O8: 6 | V8: 6 | AC8: 6 | AJ8: 6 | AQ8: 6 | AX8: 6 | BE8: 6 | BL8: 6 | BS8: 6 | BZ8: 6 | CG8: 6
A9: 7 | H9: 7 | O9: 7 | V9: 7 | AC9: 7 | AJ9: 7 | AQ9: 7 | AX9: 7 | BE9: 7 | BL9: 7 | BS9: 7 | BZ9: 7 | CG9: 7
A10: 8 | H10: 8 | O10: 8 | V10: 8 | AA10: 0 | AC10: 8 | AJ10: 8 | AQ10: 8 | AX10: 8 | BE10: 8 | BL10: 8 | BS10: 8 | BZ10: 8 | CG10: 8
A11: 9 | H11: 9 | O11: 9 | V11: 9 | AC11: 9 | AJ11: 9 | AQ11: 9 | AX11: 9 | BE11: 9 | BL11: 9 | BS11: 9 | BZ11: 9 | CG11: 9
A12: 10 | H12: 10 | O12: 10 | V12: 10 | AC12: 10 | AJ12: 10 | AQ12: 10 | AX12: 10 | BE12: 10 | BL12: 10 | BS12: 10 | BZ12: 10 | CG12: 10
A13: 11 | H13: 11 | O13: 11 | V13: 11 | AC13: 11 | AJ13: 11 | AQ13: 11 | AX13: 11 | BE13: 11 | BL13: 11 | BS13: 11 | BZ13: 11 | CG13: 11
A14: 12 | H14: 12 | O14: 12 | V14: 12 | AC14: 12 | AJ14: 12 | AQ14: 12 | AX14: 12 | BE14: 12 | BL14: 12 | BS14: 12 | BZ14: 12 | CG14: 12
A15: 13 | H15: 13 | O15: 13 | V15: 13 | AC15: 13 | AJ15: 13 | AQ15: 13 | AX15: 13 | BE15: 13 | BL15: 13 | BS15: 13 | BZ15: 13 | CG15: 13
A16: 14 | H16: 14 | O16: 14 | V16: 14 | AC16: 14 | AJ16: 14 | AQ16: 14 | AX16: 14 | BE16: 14 | BL16: 14 | BS16: 14 | BZ16: 14 | CG16: 14
A17: 15 | H17: 15 | O17: 15 | V17: 15 | AC17: 15 | AJ17: 15 | AQ17: 15 | AX17: 15 | BE17: 15 | BL17: 15 | BS17: 15 | BZ17: 15 | CG17: 15
A18: 16 | H18: 16 | O18: 16 | V18: 16 | AC18: 16 | AJ18: 16 | AQ18: 16 | AX18: 16 | BE18: 16 | BL18: 16 | BS18: 16 | BZ18: 16 | CG18: 16
A19: 17 | H19: 17 | O19: 17 | V19: 17 | AC19: 17 | AJ19: 17 | AQ19: 17 | AX19: 17 | BE19: 17 | BL19: 17 | BS19: 17 | BZ19: 17 | CG19: 17
A20: 18 | H20: 18 | O20: 18 | V20: 18 | AC20: 18 | AJ20: 18 | AQ20: 18 | AX20: 18 | BE20: 18 | BL20: 18 | BS20: 18 | BZ20: 18 | CG20: 18
A21: 19 | H21: 19 | O21: 19 | V21: 19 | AC21: 19 | AJ21: 19 | AQ21: 19 | AX21: 19 | BE21: 19 | BL21: 19 | BS21: 19 | BZ21: 19 | CG21: 19
A22: 20 | H22: 20 | O22: 20 | V22: 20 | AC22: 20 | AJ22: 20 | AQ22: 20 | AX22: 20 | BE22: 20 | BL22: 20 | BS22: 20 | BZ22: 20 | CG22: 20
... A63: 61 | H63: 61 | O63: 61 | V63: 61 | AC63: 61 | AJ63: 61 | AQ63: 61 | AX63: 61 | BE63: 61 | BL63: 61 | BS63: 61 | BZ63: 61 | CG63: 61
A64: TOTAL RECIBIDO: | C64: =SUM(C3:C63) -> 0 | E64: =SUM(E3:E63) -> 0 | F64: =SUM(F3:F63) -> 0 | H64: TOTAL RECIBIDO: | J64: =SUM(J3:J63) -> 0 | L64: =SUM(L3:L63) -> 0 | M64: =SUM(M3:M63) -> 0 | O64: TOTAL RECIBIDO: | Q64: =SUM(Q3:Q63) -> 0 | S64: =SUM(S3:S63) -> 0 | T64: =SUM(T3:T63) -> 934 | V64: TOTAL RECIBIDO: | X64: =SUM(X3:X63) -> 5601.92 | Z64: =SUM(Z3:Z63) -> 8 | AA64: =SUM(AA3:AA63) -> 0 | AC64: TOTAL RECIBIDO: | AE64: =SUM(AE3:AE63) -> 0 | AG64: =SUM(AG3:AG63) -> 0 | AH64: =SUM(AH3:AH63) -> 0 | AJ64: TOTAL RECIBIDO: | AL64: =SUM(AL3:AL63) -> 69895.8 | AN64: =SUM(AN3:AN63) -> 107.12 | AO64: =SUM(AO3:AO63) -> 0 | AQ64: TOTAL RECIBIDO: | AS64: =SUM(AS3:AS63) -> 0 | AU64: =SUM(AU3:AU63) -> 0 | AV64: =SUM(AV3:AV63) -> 0 | AX64: TOTAL RECIBIDO: | AZ64: =SUM(AZ3:AZ63) -> 0 | BB64: =SUM(BB3:BB63) -> 0 | BC64: =SUM(BC3:BC63) -> 0 | BE64: TOTAL RECIBIDO: | BG64: =SUM(BG3:BG63) -> 179759.41 | BI64: =SUM(BI3:BI63) -> 265.00086 | BJ64: =SUM(BJ3:BJ63) -> 0 | BL64: TOTAL RECIBIDO: | BN64: =SUM(BN3:BN63) -> 0 | BP64: =SUM(BP3:BP63) -> 0 | BQ64: =SUM(BQ3:BQ63) -> 233 | BS64: TOTAL RECIBIDO: | BU64: =SUM(BU3:BU63) -> 0 | BW64: =SUM(BW3:BW63) -> 0 | BX64: =SUM(BX3:BX63) -> 0 | BZ64: TOTAL RECIBIDO: | CB64: =SUM(CB3:CB63) -> 0 | CD64: =SUM(CD3:CD63) -> 0 | CE64: =SUM(CE3:CE63) -> 0 | CG64: TOTAL RECIBIDO: | CI64: =SUM(CI3:CI63) -> 0 | CK64: =SUM(CK3:CK63) -> 0 | CL64: =SUM(CL3:CL63) -> 0
A65: TOTAL A DEDUCIR DEL CREDITO: | F65: =E64+F64 -> 0 | H65: TOTAL A DEDUCIR DEL CREDITO: | M65: =L64+M64 -> 0 | O65: TOTAL A DEDUCIR DEL CREDITO: | T65: =S64+T64 -> 934 | V65: TOTAL A DEDUCIR DEL CREDITO: | AA65: =Z64+AA64 -> 8 | AC65: TOTAL A DEDUCIR DEL CREDITO: | AH65: =AG64+AH64 -> 0 | AJ65: TOTAL A DEDUCIR DEL CREDITO: | AO65: =AN64+AO64 -> 107.12 | AQ65: TOTAL A DEDUCIR DEL CREDITO: | AV65: =AU64+AV64 -> 0 | AX65: TOTAL A DEDUCIR DEL CREDITO: | BC65: =BB64+BC64 -> 0 | BE65: TOTAL A DEDUCIR DEL CREDITO: | BJ65: =BI64+BJ64 -> 265.00086 | BL65: TOTAL A DEDUCIR DEL CREDITO: | BQ65: =BP64+BQ64 -> 233 | BS65: TOTAL A DEDUCIR DEL CREDITO: | BX65: =BW64+BX64 -> 0 | BZ65: TOTAL A DEDUCIR DEL CREDITO: | CE65: =CD64+CE64 -> 0 | CG65: TOTAL A DEDUCIR DEL CREDITO: | CL65: =CK64+CL64 -> 0
A71: TOTAL BOLIVARES: | C71: =C64+J64+Q64+X64+AE64+AL64+AS64+AZ64+BG64+BN64+BU64+CB64+CI64 -> 255257.13
A72: TOTAL DOLARES: | C72: =F64+M64+T64+AA64+AH64+AO64+AV64+BC64+BJ64+BQ64+BX64+CE64+CL64 -> 1167

Sheet INGRESOS VS EGRESO 
A1: INGRESOS
A2: ITEM | B2: FECHA | D2: BOLIVARES EFECTIVO Y BANCO | E2: DOLARES EFECTIVO Y ZELLE | K2: FECHA | L2: TASA BCV | M2: TASA EURO | N2: TASA BINANCE
A3: 1 | C3: INICIAL WENDY | D3: 0 | E3: 0
A4: 2 | C4: INICIAL INDIV. | D4: 490 | E4: 158 | F4: CAJA CHICA | G4: 490 | H4: 158
A5: 1 | C5: WENDY | D5: ='INGRESO WENDY'!E64 -> 989768.9 | E5: =+'INGRESO WENDY'!J64+'INGRESO WENDY'!K64 -> 862 | K5: 46149 | L5: 496.83 | M5: 583.86 | N5: 652.5
A6: 2 | C6: INDIVIDUAL | D6: =+'INGRESO DETALLADO INDIVIDUAL'!C71 -> 255257.13 | E6: =+'INGRESO DETALLADO INDIVIDUAL'!C72 -> 1167 | K6: 46150 | L6: 499.86 | M6: 588.09 | N6: 658.7
A7: TOTAL INGRESO: | D7: =SUM(D3:D6) -> 1245516 | E7: =SUM(E3:E6) -> 2187 | K7: 46153 | L7: 500.46 | M7: 589.27 | N7: 647.6
K8: 46154 | L8: 504.91 | M8: 595.05 | N8: 651.84
H9: CAJA CHICA | I9: 158 | K9: 46155 | L9: 508.6 | M9: 596.6 | N9: 660.27
A10: EGRESOS | H10: INGRESOS $ | I10: =+'INGRESO WENDY'!J64+'INGRESO DETALLADO INDIVIDUAL'!C72+'INGRESO WENDY'!K64 -> 2029 | K10: 46156 | L10: 510.78 | M10: 598.12 | N10: 665.51
A11: ITEM | B11: FECHA | C11: NOTA | D11: BOLIVARES | E11: DOLARES | H11: EGRESOS | I11: =+E70 -> 1830 | K11: 46157 | L11: 515.18 | M11: 601.45 | N11: 672.94
A12: 1 | B12: 46149 | C12: 006 | E12: 50 | F12: JESUS R, | H12: CAJA | I12: =+I9+I10-I11 -> 357 | K12: 46160 | L12: 517.96 | M12: 602.18 | N12: 700.24
A13: 2 | B13: 46149 | C13: 007 | E13: 174 | F13: JESUS RUIZ RETIRO | K13: 46161 | L13: 517.96 | M13: 602.18 | N13: 714.74
A14: 3 | B14: 46149 | C14: 008 | E14: 107 | F14: JOHAN | K14: 46162 | L14: 520.91 | M14: 604.15 | N14: 703.59
A15: 4 | B15: 46149 | C15: 009 | D15: 69895.8 | F15: BANCO TESORO | H15: JESUS VUELTO 4 | I15: 4 | K15: 46163 | L15: 523.67 | M15: 609.34 | N15: 712.74
A16: 5 | B16: 46149 | C16: 010 | H16: JESUS VUELTO 5 | I16: 2
A17: 6 | B17: 46149 | C17: 011 | D17: 67503.89 | F17: BANCO TESORO | H17: JESUS VUELTO 5 | I17: 5
A18: 7 | B18: 46150 | C18: 012 | D18: 146824.6 | F18: BANCO TESORO
A19: 8 | B19: 46153 | C19: 013 | D19: 49217.6 | F19: BANCO TESORO | I19: =+I12+I15+I16+I17+I18 -> 368
A20: 9 | B20: 46154 | C20: 014 | D20: 48236.16 | F20: BANCO TESORO | H20: EFECTIVO | I20: =+D74 -> 2490.098
A21: 10 | B21: 46154 | C21: 015 | D21: 0 | E21: 106 | F21: ZELLE
A22: 11 | B22: 46155 | C22: 016 | D22: 46218.9 | F22: BANCO TESORO
A23: 12 | B23: 46155 | C23: 017 | D23: 109340.72 | F23: RECIBO PAGO MOVIL DANYELLO
A24: 13 | B24: 46155 | C24: 018 | D24: 12148.97 | F24: COMISION DANYELLO
A25: 14 | B25: 46156 | C25: 019 | D25: 34606.52 | F25: BANCO TESORO
A26: 15 | B26: 46157 | C26: 020 | E26: 160 | F26: ZELLE
A27: 16 | B27: 46157 | C27: 021 | D27: =37011.7+4710.57+20861.12 -> 62583.39 | F27: BANCO TESORO
A28: 17 | B28: 46160 | C28: 022 | D28: =71424.19+23808.16 -> 95232.35 | F28: BANCO TESORO
A29: 18 | B29: 46160 | C29: 023 | E29: 165 | F29: ZELLE
A30: 19 | B30: 46160 | C30: 024 | D30: 5601.92 | F30: ESTADO DE CUENTA REV BANESCO
A31: 20 | B31: 46161 | C31: 025 | D31: 0 | E31: 60 | F31: HOJAS BLANCAS
A32: 21 | B32: 46162 | C32: 026 | D32: =23218.47+48547.71 -> 71766.18 | F32: ESTADO DE CUENTA REV
A33: 22 | B33: 46164 | C33: 027 | E33: 100 | F33: MECANICO JOHAN
A34: 23 | B34: 46163 | C34: 028 | D34: =13542.06+14254.8 -> 27796.86 | F34: ESTADO DE CUENTA
A35: 24 | B35: 46164 | C35: 029 | D35: =24926+27189+5008.5 -> 57123.5 | F35: ESTADO DE CUENTA
A36: 25 | B36: 46160 | C36: 030 | D36: 33486 | F36: ESTADO DE CUENTA
A37: 26 | B37: 46167 | C37: 031 | D37: =134788.63+8696.04+5072.69 -> 148557.36 | F37: ESTADO DE CUENTA
A38: 27 | B38: 46167 | C38: 032 | D38: 24783.72 | F38: PAGO DANYELLO REV
A39: 28 | B39: 46167 | C39: 033 | E39: 40 | F39: SR GUSTAVO
A40: 29 | C40: 034 | E40: 10 | F40: JESUS RUIZ RETIRO
...

Sheet RECIBOS
D4: RECIBO DE PAGO
I6: RECIBO Nº | J6: 33 | P6: =87*2 -> 174
P7: =174-200 -> -26
I8: POR: | J8: 40$
D11: QUIEN RECIBE SR.(A): | E11: GUSTAVO | I11: LA CANTIDAD DE: | J11: =+J8 -> 40$
D12: CANTIDAD EN LETRAS: | E12: CUARENTA $
D13: POR CONCEPTO DE: | E13: SR GUSTAVO AUTORIZA JESUS RUIZ
D15: FECHA: | E15: 46167 | K15: =CONCATENATE(UPPER(TEXT(E15,"dddd dd \d\e mmmm \d\e yyyy"))) -> LUNES 25 DE MAYO DE 2026
E18: RECIBÍ CONFORME | I18: ENTREGUÉ CONFORME
